Workbook

Sheet 입력
A1: OLIBANA — 공급자 견적 입력
A2: 노란 셀만 입력합니다. 계산은 '계산' 시트에서 자동으로 이뤄집니다.
A3: B열 '예시'는 입력 형식을 보여주기 위한 가상 수치입니다. 실제 견적이 아니므로 무시하거나 지우십시오.
A5: [1] 공통 가정 | B5: 예시 | C5: ← 여기에 입력
A6: 통화 (예: JPY / KRW / USD) | B6: JPY | G6: 결제 수수료는 Stripe 기준 2.9% + 건당 고정액. 통화에 맞춰 조정.
A7: 판매가 (장당) | B7: 68000
A8: 결제 수수료율 | B8: 0.029
A9: 결제 고정 수수료 (건당) | B9: 50
A10: 배송 보조 (장당) | B10: 1500 | G10: 반품 충당률: 실측 불가. 보수적으로 잡고 판매 후 교체.
A11: 반품 충당률 | B11: 0.05
A13: [2] 공급자별 고정비 · 조건
A14: 항목 | B14: 예시 | C14: 공급자 1 | D14: 공급자 2 | E14: 공급자 3
A15: 공급자명 | B15: (예시) | G15: MOQ가 손익분기 수량보다 크면, 그 공급자로는 pre-order 최소 수량을 MOQ에 맞춰야 한다.
A16: 패턴 제작비 | B16: 30000
A17: 그레이딩비 | B17: 15000
A18: 샘플비 | B18: 25000
A19: MOQ (최소 수량) | B19: 50
A20: 리드타임 (일, 발주→출고) | B20: 60
A21: 원단 최소 구매 단위 | B21: 반 1본 | G21: 원단 MOQ가 봉제 MOQ보다 큰 경우가 흔하다. 실질 MOQ를 결정하므로 반드시 확인.
A24: [3] 수량 구간별 장당 변동원가
A25: 공급자마다 아래 블록을 채웁니다. 수량 구간은 견적 요청과 동일하게 유지하십시오.
A27: 예시 (무시/삭제)
A28: 수량 | B28: 임가공(CMT) | C28: 원단 | D28: 부자재 | E28: 라벨 | F28: 포장
A29: 10 | B29: 12000 | C29: 8000 | D29: 2000 | E29: 300 | F29: 500
A30: 20 | B30: 10000 | C30: 7500 | D30: 1800 | E30: 280 | F30: 450
A31: 30 | B31: 9000 | C31: 7000 | D31: 1700 | E31: 260 | F31: 430
A32: 50 | B32: 8000 | C32: 6500 | D32: 1600 | E32: 250 | F32: 400
A33: 100 | B33: 7000 | C33: 6000 | D33: 1500 | E33: 230 | F33: 380
A35: 공급자 1
A36: 수량 | B36: 임가공(CMT) | C36: 원단 | D36: 부자재 | E36: 라벨 | F36: 포장
A37: 10
A38: 20
A39: 30
A40: 50
A41: 100
A43: 공급자 2
A44: 수량 | B44: 임가공(CMT) | C44: 원단 | D44: 부자재 | E44: 라벨 | F44: 포장
A45: 10
A46: 20
A47: 30
...

Sheet 계산
A1: OLIBANA — 손익분기 계산
A2: '입력' 시트를 채우면 자동 계산됩니다. 이 시트는 편집하지 마십시오.
A4: 예시 (무시/삭제)
A5: 수량 | B5: 변동원가/장 | C5: 고정비배분/장 | D5: 실원가/장 | E5: 결제수수료/장 | F5: 배송보조/장 | G5: 반품충당/장 | H5: 기여이익/장 | I5: 기여이익률 | J5: 판정
A6: =입력!A29 | B6: =IF(COUNT(입력!B29:F29)=0,"",SUM(입력!B29:F29)) | C6: =IF(입력!A29=0,"",IFERROR((입력!B16+입력!B17+입력!B18)/입력!A29,"")) | D6: =IF(OR(B6="",C6=""),"",B6+C6) | E6: =IF(입력!B7="","",입력!B7*입력!B8+입력!B9) | F6: =입력!B10 | G6: =IF(입력!B7="","",입력!B7*입력!B11) | H6: =IF(D6="","",입력!B7-D6-E6-F6-G6) | I6: =IF(OR(H6="",입력!B7="",입력!B7=0),"",H6/입력!B7) | J6: =IF(H6="","-",IF(H6>0,"흑자","적자"))
A7: =입력!A30 | B7: =IF(COUNT(입력!B30:F30)=0,"",SUM(입력!B30:F30)) | C7: =IF(입력!A30=0,"",IFERROR((입력!B16+입력!B17+입력!B18)/입력!A30,"")) | D7: =IF(OR(B7="",C7=""),"",B7+C7) | E7: =IF(입력!B7="","",입력!B7*입력!B8+입력!B9) | F7: =입력!B10 | G7: =IF(입력!B7="","",입력!B7*입력!B11) | H7: =IF(D7="","",입력!B7-D7-E7-F7-G7) | I7: =IF(OR(H7="",입력!B7="",입력!B7=0),"",H7/입력!B7) | J7: =IF(H7="","-",IF(H7>0,"흑자","적자"))
A8: =입력!A31 | B8: =IF(COUNT(입력!B31:F31)=0,"",SUM(입력!B31:F31)) | C8: =IF(입력!A31=0,"",IFERROR((입력!B16+입력!B17+입력!B18)/입력!A31,"")) | D8: =IF(OR(B8="",C8=""),"",B8+C8) | E8: =IF(입력!B7="","",입력!B7*입력!B8+입력!B9) | F8: =입력!B10 | G8: =IF(입력!B7="","",입력!B7*입력!B11) | H8: =IF(D8="","",입력!B7-D8-E8-F8-G8) | I8: =IF(OR(H8="",입력!B7="",입력!B7=0),"",H8/입력!B7) | J8: =IF(H8="","-",IF(H8>0,"흑자","적자"))
A9: =입력!A32 | B9: =IF(COUNT(입력!B32:F32)=0,"",SUM(입력!B32:F32)) | C9: =IF(입력!A32=0,"",IFERROR((입력!B16+입력!B17+입력!B18)/입력!A32,"")) | D9: =IF(OR(B9="",C9=""),"",B9+C9) | E9: =IF(입력!B7="","",입력!B7*입력!B8+입력!B9) | F9: =입력!B10 | G9: =IF(입력!B7="","",입력!B7*입력!B11) | H9: =IF(D9="","",입력!B7-D9-E9-F9-G9) | I9: =IF(OR(H9="",입력!B7="",입력!B7=0),"",H9/입력!B7) | J9: =IF(H9="","-",IF(H9>0,"흑자","적자"))
A10: =입력!A33 | B10: =IF(COUNT(입력!B33:F33)=0,"",SUM(입력!B33:F33)) | C10: =IF(입력!A33=0,"",IFERROR((입력!B16+입력!B17+입력!B18)/입력!A33,"")) | D10: =IF(OR(B10="",C10=""),"",B10+C10) | E10: =IF(입력!B7="","",입력!B7*입력!B8+입력!B9) | F10: =입력!B10 | G10: =IF(입력!B7="","",입력!B7*입력!B11) | H10: =IF(D10="","",입력!B7-D10-E10-F10-G10) | I10: =IF(OR(H10="",입력!B7="",입력!B7=0),"",H10/입력!B7) | J10: =IF(H10="","-",IF(H10>0,"흑자","적자"))
A11: 손익분기 수량 | B11: =IF(COUNT(H6:H10)=0,"입력 대기",IF(COUNTIF(H6:H10,"<=0")>=5,"구간 내 흑자 없음",INDEX(A6:A10,COUNTIF(H6:H10,"<=0")+1))) | C11: ← pre-order 최소 수량 | E11: =IF(입력!B19="","",IF(ISNUMBER(B11)=FALSE,"",IF(입력!B19>B11,"⚠ MOQ > 손익분기 → 실질 최소수량은 MOQ","MOQ 충족")))
A13: 공급자 1
A14: 수량 | B14: 변동원가/장 | C14: 고정비배분/장 | D14: 실원가/장 | E14: 결제수수료/장 | F14: 배송보조/장 | G14: 반품충당/장 | H14: 기여이익/장 | I14: 기여이익률 | J14: 판정
A15: =입력!A37 | B15: =IF(COUNT(입력!B37:F37)=0,"",SUM(입력!B37:F37)) | C15: =IF(입력!A37=0,"",IFERROR((입력!C16+입력!C17+입력!C18)/입력!A37,"")) | D15: =IF(OR(B15="",C15=""),"",B15+C15) | E15: =IF(입력!C7="","",입력!C7*입력!C8+입력!C9) | F15: =입력!C10 | G15: =IF(입력!C7="","",입력!C7*입력!C11) | H15: =IF(D15="","",입력!C7-D15-E15-F15-G15) | I15: =IF(OR(H15="",입력!C7="",입력!C7=0),"",H15/입력!C7) | J15: =IF(H15="","-",IF(H15>0,"흑자","적자"))
A16: =입력!A38 | B16: =IF(COUNT(입력!B38:F38)=0,"",SUM(입력!B38:F38)) | C16: =IF(입력!A38=0,"",IFERROR((입력!C16+입력!C17+입력!C18)/입력!A38,"")) | D16: =IF(OR(B16="",C16=""),"",B16+C16) | E16: =IF(입력!C7="","",입력!C7*입력!C8+입력!C9) | F16: =입력!C10 | G16: =IF(입력!C7="","",입력!C7*입력!C11) | H16: =IF(D16="","",입력!C7-D16-E16-F16-G16) | I16: =IF(OR(H16="",입력!C7="",입력!C7=0),"",H16/입력!C7) | J16: =IF(H16="","-",IF(H16>0,"흑자","적자"))
A17: =입력!A39 | B17: =IF(COUNT(입력!B39:F39)=0,"",SUM(입력!B39:F39)) | C17: =IF(입력!A39=0,"",IFERROR((입력!C16+입력!C17+입력!C18)/입력!A39,"")) | D17: =IF(OR(B17="",C17=""),"",B17+C17) | E17: =IF(입력!C7="","",입력!C7*입력!C8+입력!C9) | F17: =입력!C10 | G17: =IF(입력!C7="","",입력!C7*입력!C11) | H17: =IF(D17="","",입력!C7-D17-E17-F17-G17) | I17: =IF(OR(H17="",입력!C7="",입력!C7=0),"",H17/입력!C7) | J17: =IF(H17="","-",IF(H17>0,"흑자","적자"))
A18: =입력!A40 | B18: =IF(COUNT(입력!B40:F40)=0,"",SUM(입력!B40:F40)) | C18: =IF(입력!A40=0,"",IFERROR((입력!C16+입력!C17+입력!C18)/입력!A40,"")) | D18: =IF(OR(B18="",C18=""),"",B18+C18) | E18: =IF(입력!C7="","",입력!C7*입력!C8+입력!C9) | F18: =입력!C10 | G18: =IF(입력!C7="","",입력!C7*입력!C11) | H18: =IF(D18="","",입력!C7-D18-E18-F18-G18) | I18: =IF(OR(H18="",입력!C7="",입력!C7=0),"",H18/입력!C7) | J18: =IF(H18="","-",IF(H18>0,"흑자","적자"))
A19: =입력!A41 | B19: =IF(COUNT(입력!B41:F41)=0,"",SUM(입력!B41:F41)) | C19: =IF(입력!A41=0,"",IFERROR((입력!C16+입력!C17+입력!C18)/입력!A41,"")) | D19: =IF(OR(B19="",C19=""),"",B19+C19) | E19: =IF(입력!C7="","",입력!C7*입력!C8+입력!C9) | F19: =입력!C10 | G19: =IF(입력!C7="","",입력!C7*입력!C11) | H19: =IF(D19="","",입력!C7-D19-E19-F19-G19) | I19: =IF(OR(H19="",입력!C7="",입력!C7=0),"",H19/입력!C7) | J19: =IF(H19="","-",IF(H19>0,"흑자","적자"))
A20: 손익분기 수량 | B20: =IF(COUNT(H15:H19)=0,"입력 대기",IF(COUNTIF(H15:H19,"<=0")>=5,"구간 내 흑자 없음",INDEX(A15:A19,COUNTIF(H15:H19,"<=0")+1))) | C20: ← pre-order 최소 수량 | E20: =IF(입력!C19="","",IF(ISNUMBER(B20)=FALSE,"",IF(입력!C19>B20,"⚠ MOQ > 손익분기 → 실질 최소수량은 MOQ","MOQ 충족")))
A22: 공급자 2
A23: 수량 | B23: 변동원가/장 | C23: 고정비배분/장 | D23: 실원가/장 | E23: 결제수수료/장 | F23: 배송보조/장 | G23: 반품충당/장 | H23: 기여이익/장 | I23: 기여이익률 | J23: 판정
A24: =입력!A45 | B24: =IF(COUNT(입력!B45:F45)=0,"",SUM(입력!B45:F45)) | C24: =IF(입력!A45=0,"",IFERROR((입력!D16+입력!D17+입력!D18)/입력!A45,"")) | D24: =IF(OR(B24="",C24=""),"",B24+C24) | E24: =IF(입력!C7="","",입력!C7*입력!C8+입력!C9) | F24: =입력!C10 | G24: =IF(입력!C7="","",입력!C7*입력!C11) | H24: =IF(D24="","",입력!C7-D24-E24-F24-G24) | I24: =IF(OR(H24="",입력!C7="",입력!C7=0),"",H24/입력!C7) | J24: =IF(H24="","-",IF(H24>0,"흑자","적자"))
A25: =입력!A46 | B25: =IF(COUNT(입력!B46:F46)=0,"",SUM(입력!B46:F46)) | C25: =IF(입력!A46=0,"",IFERROR((입력!D16+입력!D17+입력!D18)/입력!A46,"")) | D25: =IF(OR(B25="",C25=""),"",B25+C25) | E25: =IF(입력!C7="","",입력!C7*입력!C8+입력!C9) | F25: =입력!C10 | G25: =IF(입력!C7="","",입력!C7*입력!C11) | H25: =IF(D25="","",입력!C7-D25-E25-F25-G25) | I25: =IF(OR(H25="",입력!C7="",입력!C7=0),"",H25/입력!C7) | J25: =IF(H25="","-",IF(H25>0,"흑자","적자"))
A26: =입력!A47 | B26: =IF(COUNT(입력!B47:F47)=0,"",SUM(입력!B47:F47)) | C26: =IF(입력!A47=0,"",IFERROR((입력!D16+입력!D17+입력!D18)/입력!A47,"")) | D26: =IF(OR(B26="",C26=""),"",B26+C26) | E26: =IF(입력!C7="","",입력!C7*입력!C8+입력!C9) | F26: =입력!C10 | G26: =IF(입력!C7="","",입력!C7*입력!C11) | H26: =IF(D26="","",입력!C7-D26-E26-F26-G26) | I26: =IF(OR(H26="",입력!C7="",입력!C7=0),"",H26/입력!C7) | J26: =IF(H26="","-",IF(H26>0,"흑자","적자"))
A27: =입력!A48 | B27: =IF(COUNT(입력!B48:F48)=0,"",SUM(입력!B48:F48)) | C27: =IF(입력!A48=0,"",IFERROR((입력!D16+입력!D17+입력!D18)/입력!A48,"")) | D27: =IF(OR(B27="",C27=""),"",B27+C27) | E27: =IF(입력!C7="","",입력!C7*입력!C8+입력!C9) | F27: =입력!C10 | G27: =IF(입력!C7="","",입력!C7*입력!C11) | H27: =IF(D27="","",입력!C7-D27-E27-F27-G27) | I27: =IF(OR(H27="",입력!C7="",입력!C7=0),"",H27/입력!C7) | J27: =IF(H27="","-",IF(H27>0,"흑자","적자"))
A28: =입력!A49 | B28: =IF(COUNT(입력!B49:F49)=0,"",SUM(입력!B49:F49)) | C28: =IF(입력!A49=0,"",IFERROR((입력!D16+입력!D17+입력!D18)/입력!A49,"")) | D28: =IF(OR(B28="",C28=""),"",B28+C28) | E28: =IF(입력!C7="","",입력!C7*입력!C8+입력!C9) | F28: =입력!C10 | G28: =IF(입력!C7="","",입력!C7*입력!C11) | H28: =IF(D28="","",입력!C7-D28-E28-F28-G28) | I28: =IF(OR(H28="",입력!C7="",입력!C7=0),"",H28/입력!C7) | J28: =IF(H28="","-",IF(H28>0,"흑자","적자"))
A29: 손익분기 수량 | B29: =IF(COUNT(H24:H28)=0,"입력 대기",IF(COUNTIF(H24:H28,"<=0")>=5,"구간 내 흑자 없음",INDEX(A24:A28,COUNTIF(H24:H28,"<=0")+1))) | C29: ← pre-order 최소 수량 | E29: =IF(입력!D19="","",IF(ISNUMBER(B29)=FALSE,"",IF(입력!D19>B29,"⚠ MOQ > 손익분기 → 실질 최소수량은 MOQ","MOQ 충족")))
A31: 공급자 3
A32: 수량 | B32: 변동원가/장 | C32: 고정비배분/장 | D32: 실원가/장 | E32: 결제수수료/장 | F32: 배송보조/장 | G32: 반품충당/장 | H32: 기여이익/장 | I32: 기여이익률 | J32: 판정
A33: =입력!A53 | B33: =IF(COUNT(입력!B53:F53)=0,"",SUM(입력!B53:F53)) | C33: =IF(입력!A53=0,"",IFERROR((입력!E16+입력!E17+입력!E18)/입력!A53,"")) | D33: =IF(OR(B33="",C33=""),"",B33+C33) | E33: =IF(입력!C7="","",입력!C7*입력!C8+입력!C9) | F33: =입력!C10 | G33: =IF(입력!C7="","",입력!C7*입력!C11) | H33: =IF(D33="","",입력!C7-D33-E33-F33-G33) | I33: =IF(OR(H33="",입력!C7="",입력!C7=0),"",H33/입력!C7) | J33: =IF(H33="","-",IF(H33>0,"흑자","적자"))
A34: =입력!A54 | B34: =IF(COUNT(입력!B54:F54)=0,"",SUM(입력!B54:F54)) | C34: =IF(입력!A54=0,"",IFERROR((입력!E16+입력!E17+입력!E18)/입력!A54,"")) | D34: =IF(OR(B34="",C34=""),"",B34+C34) | E34: =IF(입력!C7="","",입력!C7*입력!C8+입력!C9) | F34: =입력!C10 | G34: =IF(입력!C7="","",입력!C7*입력!C11) | H34: =IF(D34="","",입력!C7-D34-E34-F34-G34) | I34: =IF(OR(H34="",입력!C7="",입력!C7=0),"",H34/입력!C7) | J34: =IF(H34="","-",IF(H34>0,"흑자","적자"))
A35: =입력!A55 | B35: =IF(COUNT(입력!B55:F55)=0,"",SUM(입력!B55:F55)) | C35: =IF(입력!A55=0,"",IFERROR((입력!E16+입력!E17+입력!E18)/입력!A55,"")) | D35: =IF(OR(B35="",C35=""),"",B35+C35) | E35: =IF(입력!C7="","",입력!C7*입력!C8+입력!C9) | F35: =입력!C10 | G35: =IF(입력!C7="","",입력!C7*입력!C11) | H35: =IF(D35="","",입력!C7-D35-E35-F35-G35) | I35: =IF(OR(H35="",입력!C7="",입력!C7=0),"",H35/입력!C7) | J35: =IF(H35="","-",IF(H35>0,"흑자","적자"))
A36: =입력!A56 | B36: =IF(COUNT(입력!B56:F56)=0,"",SUM(입력!B56:F56)) | C36: =IF(입력!A56=0,"",IFERROR((입력!E16+입력!E17+입력!E18)/입력!A56,"")) | D36: =IF(OR(B36="",C36=""),"",B36+C36) | E36: =IF(입력!C7="","",입력!C7*입력!C8+입력!C9) | F36: =입력!C10 | G36: =IF(입력!C7="","",입력!C7*입력!C11) | H36: =IF(D36="","",입력!C7-D36-E36-F36-G36) | I36: =IF(OR(H36="",입력!C7="",입력!C7=0),"",H36/입력!C7) | J36: =IF(H36="","-",IF(H36>0,"흑자","적자"))
A37: =입력!A57 | B37: =IF(COUNT(입력!B57:F57)=0,"",SUM(입력!B57:F57)) | C37: =IF(입력!A57=0,"",IFERROR((입력!E16+입력!E17+입력!E18)/입력!A57,"")) | D37: =IF(OR(B37="",C37=""),"",B37+C37) | E37: =IF(입력!C7="","",입력!C7*입력!C8+입력!C9) | F37: =입력!C10 | G37: =IF(입력!C7="","",입력!C7*입력!C11) | H37: =IF(D37="","",입력!C7-D37-E37-F37-G37) | I37: =IF(OR(H37="",입력!C7="",입력!C7=0),"",H37/입력!C7) | J37: =IF(H37="","-",IF(H37>0,"흑자","적자"))
A38: 손익분기 수량 | B38: =IF(COUNT(H33:H37)=0,"입력 대기",IF(COUNTIF(H33:H37,"<=0")>=5,"구간 내 흑자 없음",INDEX(A33:A37,COUNTIF(H33:H37,"<=0")+1))) | C38: ← pre-order 최소 수량 | E38: =IF(입력!E19="","",IF(ISNUMBER(B38)=FALSE,"",IF(입력!E19>B38,"⚠ MOQ > 손익분기 → 실질 최소수량은 MOQ","MOQ 충족")))
A41: 판정 기준
A42: 기여이익/장 > 0 이 되는 최소 수량이 손익분기 수량이며, 그것이 pre-order 최소 수량이 된다.
A43: MOQ가 손익분기 수량보다 크면, 실질 최소 수량은 MOQ다.
A44: '구간 내 흑자 없음'이 나오면 판매가가 낮거나 원가가 높다. 가격 재검토 또는 품목 변경.
A45: 입력이 비어 있으면 계산하지 않는다. 빈칸을 0으로 채우면 적자 상품이 흑자로 보인다.

Sheet 읽는법
A1: 사용법
A3: 1. '입력' 시트의 노란 셀만 채웁니다. 흰 셀과 '계산' 시트는 건드리지 않습니다.
A4: 2. B열 '예시'는 입력 형식을 보여주는 가상 수치입니다. 실제 견적이 아니며 지워도 됩니다.
A5: 3. 공급자마다 동일한 수량 구간(10/20/30/50/100)으로 견적을 받아야 비교가 성립합니다.
A6: 4. 회신이 오지 않은 항목은 비워 둡니다. 0으로 채우지 마십시오.
A8: 왜 0으로 채우면 안 되는가
A9: 0은 '비용이 없다'는 뜻입니다. 미회신은 '모른다'는 뜻입니다.
A10: 0으로 채우면 손해 나는 상품이 이익 나는 상품처럼 보입니다.
A11: 비워 두면 계산기는 계산을 거부합니다. 그것이 올바른 동작입니다.
A13: 계산 구조
A14: 실원가/장 = 변동원가(임가공+원단+부자재+라벨+포장) + 고정비(패턴+그레이딩+샘플)/수량
A15: 기여이익/장 = 판매가 − 실원가 − 결제수수료 − 배송보조 − 반품충당
... A30: docs/business/UNIT_ECONOMICS.md UNKNOWN 관리 원칙
